<?xml version="1.0" encoding="UTF-8"?>
<testng-results retried="3" ignored="3" total="7" passed="0" failed="1" skipped="0">
  <reporter-output>
  </reporter-output>
  <suite started-at="2024-12-30T11:03:20 IST" name="MasterSuite" finished-at="2024-12-30T11:04:08 IST" duration-ms="47849">
    <groups>
      <group name="sanity">
        <method signature="TC003_ValidUserLoginTest.validate_valid_user_credentials()[pri:0, instance:testCases.TC003_ValidUserLoginTest@278bb07e]" name="validate_valid_user_credentials" class="testCases.TC003_ValidUserLoginTest"/>
      </group> <!-- sanity -->
      <group name="master">
        <method signature="TC003_ValidUserLoginTest.validate_valid_user_credentials()[pri:0, instance:testCases.TC003_ValidUserLoginTest@278bb07e]" name="validate_valid_user_credentials" class="testCases.TC003_ValidUserLoginTest"/>
      </group> <!-- master -->
    </groups>
    <test started-at="2024-12-30T11:03:20 IST" name="MasterTest" finished-at="2024-12-30T11:04:08 IST" duration-ms="47849">
      <class name="testCases.TC003_ValidUserLoginTest">
        <test-method is-config="true" signature="setUp(java.lang.String,java.lang.String)[pri:0, instance:testCases.TC003_ValidUserLoginTest@278bb07e]" started-at="2024-12-30T11:03:20 IST" name="setUp" finished-at="2024-12-30T11:03:23 IST" duration-ms="3044" status="PASS">
          <params>
            <param index="0">
              <value>
                <![CDATA[chrome]]>
              </value>
            </param>
            <param index="1">
              <value>
                <![CDATA[windows]]>
              </value>
            </param>
          </params>
          <reporter-output>
          </reporter-output>
        </test-method> <!-- setUp -->
        <test-method is-config="true" signature="reNavigate()[pri:0, instance:testCases.TC003_ValidUserLoginTest@278bb07e]" started-at="2024-12-30T11:03:23 IST" name="reNavigate" finished-at="2024-12-30T11:03:24 IST" duration-ms="179" status="PASS">
          <reporter-output>
          </reporter-output>
        </test-method> <!-- reNavigate -->
        <test-method retried="true" signature="validate_valid_user_credentials()[pri:0, instance:testCases.TC003_ValidUserLoginTest@278bb07e]" started-at="2024-12-30T11:03:24 IST" name="validate_valid_user_credentials" finished-at="2024-12-30T11:03:35 IST" duration-ms="11438" status="SKIP">
          <exception class="java.lang.AssertionError">
            <message>
              <![CDATA[null]]>
            </message>
            <full-stacktrace>
              <![CDATA[java.lang.AssertionError: null
at org.testng.Assert.fail(Assert.java:111)
at org.testng.Assert.fail(Assert.java:116)
at testCases.TC003_ValidUserLoginTest.validate_valid_user_credentials(TC003_ValidUserLoginTest.java:56)
at java.base/jdk.internal.reflect.DirectMethodHandleAccessor.invoke(DirectMethodHandleAccessor.java:103)
at java.base/java.lang.reflect.Method.invoke(Method.java:580)
at org.testng.internal.invokers.MethodInvocationHelper.invokeMethod(MethodInvocationHelper.java:139)
at org.testng.internal.invokers.TestInvoker.invokeMethod(TestInvoker.java:664)
at org.testng.internal.invokers.TestInvoker.invokeTestMethod(TestInvoker.java:227)
at org.testng.internal.invokers.MethodRunner.runInSequence(MethodRunner.java:50)
at org.testng.internal.invokers.TestInvoker$MethodInvocationAgent.invoke(TestInvoker.java:957)
at org.testng.internal.invokers.TestInvoker.invokeTestMethods(TestInvoker.java:200)
at org.testng.internal.invokers.TestMethodWorker.invokeTestMethods(TestMethodWorker.java:148)
at org.testng.internal.invokers.TestMethodWorker.run(TestMethodWorker.java:128)
at java.base/java.util.ArrayList.forEach(ArrayList.java:1597)
at org.testng.TestRunner.privateRun(TestRunner.java:848)
at org.testng.TestRunner.run(TestRunner.java:621)
at org.testng.SuiteRunner.runTest(SuiteRunner.java:443)
at org.testng.SuiteRunner.runSequentially(SuiteRunner.java:437)
at org.testng.SuiteRunner.privateRun(SuiteRunner.java:397)
at org.testng.SuiteRunner.run(SuiteRunner.java:336)
at org.testng.SuiteRunnerWorker.runSuite(SuiteRunnerWorker.java:52)
at org.testng.SuiteRunnerWorker.run(SuiteRunnerWorker.java:95)
at org.testng.TestNG.runSuitesSequentially(TestNG.java:1280)
at org.testng.TestNG.runSuitesLocally(TestNG.java:1200)
at org.testng.TestNG.runSuites(TestNG.java:1114)
at org.testng.TestNG.run(TestNG.java:1082)
at org.testng.remote.AbstractRemoteTestNG.run(AbstractRemoteTestNG.java:115)
at org.testng.remote.RemoteTestNG.initAndRun(RemoteTestNG.java:293)
at org.testng.remote.RemoteTestNG.main(RemoteTestNG.java:91)
]]>
            </full-stacktrace>
          </exception> <!-- java.lang.AssertionError -->
          <reporter-output>
          </reporter-output>
        </test-method> <!-- validate_valid_user_credentials -->
        <test-method is-config="true" signature="reNavigate()[pri:0, instance:testCases.TC003_ValidUserLoginTest@278bb07e]" started-at="2024-12-30T11:03:35 IST" name="reNavigate" finished-at="2024-12-30T11:03:35 IST" duration-ms="172" status="PASS">
          <reporter-output>
          </reporter-output>
        </test-method> <!-- reNavigate -->
        <test-method retried="true" signature="validate_valid_user_credentials()[pri:0, instance:testCases.TC003_ValidUserLoginTest@278bb07e]" started-at="2024-12-30T11:03:35 IST" name="validate_valid_user_credentials" finished-at="2024-12-30T11:03:46 IST" duration-ms="10757" status="SKIP">
          <exception class="java.lang.AssertionError">
            <message>
              <![CDATA[null]]>
            </message>
            <full-stacktrace>
              <![CDATA[java.lang.AssertionError: null
at org.testng.Assert.fail(Assert.java:111)
at org.testng.Assert.fail(Assert.java:116)
at testCases.TC003_ValidUserLoginTest.validate_valid_user_credentials(TC003_ValidUserLoginTest.java:56)
at java.base/jdk.internal.reflect.DirectMethodHandleAccessor.invoke(DirectMethodHandleAccessor.java:103)
at java.base/java.lang.reflect.Method.invoke(Method.java:580)
at org.testng.internal.invokers.MethodInvocationHelper.invokeMethod(MethodInvocationHelper.java:139)
at org.testng.internal.invokers.TestInvoker.invokeMethod(TestInvoker.java:664)
at org.testng.internal.invokers.TestInvoker.retryFailed(TestInvoker.java:248)
at org.testng.internal.invokers.MethodRunner.runInSequence(MethodRunner.java:62)
at org.testng.internal.invokers.TestInvoker$MethodInvocationAgent.invoke(TestInvoker.java:957)
at org.testng.internal.invokers.TestInvoker.invokeTestMethods(TestInvoker.java:200)
at org.testng.internal.invokers.TestMethodWorker.invokeTestMethods(TestMethodWorker.java:148)
at org.testng.internal.invokers.TestMethodWorker.run(TestMethodWorker.java:128)
at java.base/java.util.ArrayList.forEach(ArrayList.java:1597)
at org.testng.TestRunner.privateRun(TestRunner.java:848)
at org.testng.TestRunner.run(TestRunner.java:621)
at org.testng.SuiteRunner.runTest(SuiteRunner.java:443)
at org.testng.SuiteRunner.runSequentially(SuiteRunner.java:437)
at org.testng.SuiteRunner.privateRun(SuiteRunner.java:397)
at org.testng.SuiteRunner.run(SuiteRunner.java:336)
at org.testng.SuiteRunnerWorker.runSuite(SuiteRunnerWorker.java:52)
at org.testng.SuiteRunnerWorker.run(SuiteRunnerWorker.java:95)
at org.testng.TestNG.runSuitesSequentially(TestNG.java:1280)
at org.testng.TestNG.runSuitesLocally(TestNG.java:1200)
at org.testng.TestNG.runSuites(TestNG.java:1114)
at org.testng.TestNG.run(TestNG.java:1082)
at org.testng.remote.AbstractRemoteTestNG.run(AbstractRemoteTestNG.java:115)
at org.testng.remote.RemoteTestNG.initAndRun(RemoteTestNG.java:293)
at org.testng.remote.RemoteTestNG.main(RemoteTestNG.java:91)
]]>
            </full-stacktrace>
          </exception> <!-- java.lang.AssertionError -->
          <reporter-output>
          </reporter-output>
        </test-method> <!-- validate_valid_user_credentials -->
        <test-method is-config="true" signature="reNavigate()[pri:0, instance:testCases.TC003_ValidUserLoginTest@278bb07e]" started-at="2024-12-30T11:03:46 IST" name="reNavigate" finished-at="2024-12-30T11:03:46 IST" duration-ms="309" status="PASS">
          <reporter-output>
          </reporter-output>
        </test-method> <!-- reNavigate -->
        <test-method retried="true" signature="validate_valid_user_credentials()[pri:0, instance:testCases.TC003_ValidUserLoginTest@278bb07e]" started-at="2024-12-30T11:03:46 IST" name="validate_valid_user_credentials" finished-at="2024-12-30T11:03:57 IST" duration-ms="10697" status="SKIP">
          <exception class="java.lang.AssertionError">
            <message>
              <![CDATA[null]]>
            </message>
            <full-stacktrace>
              <![CDATA[java.lang.AssertionError: null
at org.testng.Assert.fail(Assert.java:111)
at org.testng.Assert.fail(Assert.java:116)
at testCases.TC003_ValidUserLoginTest.validate_valid_user_credentials(TC003_ValidUserLoginTest.java:56)
at java.base/jdk.internal.reflect.DirectMethodHandleAccessor.invoke(DirectMethodHandleAccessor.java:103)
at java.base/java.lang.reflect.Method.invoke(Method.java:580)
at org.testng.internal.invokers.MethodInvocationHelper.invokeMethod(MethodInvocationHelper.java:139)
at org.testng.internal.invokers.TestInvoker.invokeMethod(TestInvoker.java:664)
at org.testng.internal.invokers.TestInvoker.retryFailed(TestInvoker.java:248)
at org.testng.internal.invokers.MethodRunner.runInSequence(MethodRunner.java:62)
at org.testng.internal.invokers.TestInvoker$MethodInvocationAgent.invoke(TestInvoker.java:957)
at org.testng.internal.invokers.TestInvoker.invokeTestMethods(TestInvoker.java:200)
at org.testng.internal.invokers.TestMethodWorker.invokeTestMethods(TestMethodWorker.java:148)
at org.testng.internal.invokers.TestMethodWorker.run(TestMethodWorker.java:128)
at java.base/java.util.ArrayList.forEach(ArrayList.java:1597)
at org.testng.TestRunner.privateRun(TestRunner.java:848)
at org.testng.TestRunner.run(TestRunner.java:621)
at org.testng.SuiteRunner.runTest(SuiteRunner.java:443)
at org.testng.SuiteRunner.runSequentially(SuiteRunner.java:437)
at org.testng.SuiteRunner.privateRun(SuiteRunner.java:397)
at org.testng.SuiteRunner.run(SuiteRunner.java:336)
at org.testng.SuiteRunnerWorker.runSuite(SuiteRunnerWorker.java:52)
at org.testng.SuiteRunnerWorker.run(SuiteRunnerWorker.java:95)
at org.testng.TestNG.runSuitesSequentially(TestNG.java:1280)
at org.testng.TestNG.runSuitesLocally(TestNG.java:1200)
at org.testng.TestNG.runSuites(TestNG.java:1114)
at org.testng.TestNG.run(TestNG.java:1082)
at org.testng.remote.AbstractRemoteTestNG.run(AbstractRemoteTestNG.java:115)
at org.testng.remote.RemoteTestNG.initAndRun(RemoteTestNG.java:293)
at org.testng.remote.RemoteTestNG.main(RemoteTestNG.java:91)
]]>
            </full-stacktrace>
          </exception> <!-- java.lang.AssertionError -->
          <reporter-output>
          </reporter-output>
        </test-method> <!-- validate_valid_user_credentials -->
        <test-method is-config="true" signature="reNavigate()[pri:0, instance:testCases.TC003_ValidUserLoginTest@278bb07e]" started-at="2024-12-30T11:03:57 IST" name="reNavigate" finished-at="2024-12-30T11:03:57 IST" duration-ms="305" status="PASS">
          <reporter-output>
          </reporter-output>
        </test-method> <!-- reNavigate -->
        <test-method signature="validate_valid_user_credentials()[pri:0, instance:testCases.TC003_ValidUserLoginTest@278bb07e]" started-at="2024-12-30T11:03:57 IST" name="validate_valid_user_credentials" finished-at="2024-12-30T11:04:08 IST" duration-ms="10708" status="FAIL">
          <exception class="java.lang.AssertionError">
            <message>
              <![CDATA[null]]>
            </message>
            <full-stacktrace>
              <![CDATA[java.lang.AssertionError: null
at org.testng.Assert.fail(Assert.java:111)
at org.testng.Assert.fail(Assert.java:116)
at testCases.TC003_ValidUserLoginTest.validate_valid_user_credentials(TC003_ValidUserLoginTest.java:56)
at java.base/jdk.internal.reflect.DirectMethodHandleAccessor.invoke(DirectMethodHandleAccessor.java:103)
at java.base/java.lang.reflect.Method.invoke(Method.java:580)
at org.testng.internal.invokers.MethodInvocationHelper.invokeMethod(MethodInvocationHelper.java:139)
at org.testng.internal.invokers.TestInvoker.invokeMethod(TestInvoker.java:664)
at org.testng.internal.invokers.TestInvoker.retryFailed(TestInvoker.java:248)
at org.testng.internal.invokers.MethodRunner.runInSequence(MethodRunner.java:62)
at org.testng.internal.invokers.TestInvoker$MethodInvocationAgent.invoke(TestInvoker.java:957)
at org.testng.internal.invokers.TestInvoker.invokeTestMethods(TestInvoker.java:200)
at org.testng.internal.invokers.TestMethodWorker.invokeTestMethods(TestMethodWorker.java:148)
at org.testng.internal.invokers.TestMethodWorker.run(TestMethodWorker.java:128)
at java.base/java.util.ArrayList.forEach(ArrayList.java:1597)
at org.testng.TestRunner.privateRun(TestRunner.java:848)
at org.testng.TestRunner.run(TestRunner.java:621)
at org.testng.SuiteRunner.runTest(SuiteRunner.java:443)
at org.testng.SuiteRunner.runSequentially(SuiteRunner.java:437)
at org.testng.SuiteRunner.privateRun(SuiteRunner.java:397)
at org.testng.SuiteRunner.run(SuiteRunner.java:336)
at org.testng.SuiteRunnerWorker.runSuite(SuiteRunnerWorker.java:52)
at org.testng.SuiteRunnerWorker.run(SuiteRunnerWorker.java:95)
at org.testng.TestNG.runSuitesSequentially(TestNG.java:1280)
at org.testng.TestNG.runSuitesLocally(TestNG.java:1200)
at org.testng.TestNG.runSuites(TestNG.java:1114)
at org.testng.TestNG.run(TestNG.java:1082)
at org.testng.remote.AbstractRemoteTestNG.run(AbstractRemoteTestNG.java:115)
at org.testng.remote.RemoteTestNG.initAndRun(RemoteTestNG.java:293)
at org.testng.remote.RemoteTestNG.main(RemoteTestNG.java:91)
]]>
            </full-stacktrace>
          </exception> <!-- java.lang.AssertionError -->
          <reporter-output>
          </reporter-output>
        </test-method> <!-- validate_valid_user_credentials -->
        <test-method is-config="true" signature="tearDown()[pri:0, instance:testCases.TC003_ValidUserLoginTest@278bb07e]" started-at="2024-12-30T11:04:08 IST" name="tearDown" finished-at="2024-12-30T11:04:08 IST" duration-ms="181" status="PASS">
          <reporter-output>
          </reporter-output>
        </test-method> <!-- tearDown -->
      </class> <!-- testCases.TC003_ValidUserLoginTest -->
    </test> <!-- MasterTest -->
  </suite> <!-- MasterSuite -->
</testng-results>
