<?xml version="1.0" encoding="UTF-8"?>
<testng-results retried="6" ignored="6" total="18" passed="3" failed="3" skipped="0">
  <reporter-output>
  </reporter-output>
  <suite started-at="2025-01-16T15:04:17 IST" name="MasterSuite" finished-at="2025-01-16T15:06:07 IST" duration-ms="110095">
    <groups>
    </groups>
    <test started-at="2025-01-16T15:04:17 IST" name="Data Driven Test" finished-at="2025-01-16T15:06:07 IST" duration-ms="110095">
      <class name="testCases.TC004_LoginDataDrivenTest">
        <test-method is-config="true" signature="setUp(java.lang.String,java.lang.String)[pri:0, instance:testCases.TC004_LoginDataDrivenTest@246f8b8b]" started-at="2025-01-16T15:04:18 IST" name="setUp" finished-at="2025-01-16T15:04:24 IST" duration-ms="6334" status="PASS">
          <params>
            <param index="0">
              <value>
                <![CDATA[edge]]>
              </value>
            </param>
            <param index="1">
              <value>
                <![CDATA[windows]]>
              </value>
            </param>
          </params>
          <reporter-output>
          </reporter-output>
        </test-method> <!-- setUp -->
        <test-method retried="true" signature="validate_login(java.lang.String,java.lang.String,java.lang.String)[pri:0, instance:testCases.TC004_LoginDataDrivenTest@246f8b8b]" started-at="2025-01-16T15:04:26 IST" name="validate_login" data-provider="loginDataProvider" finished-at="2025-01-16T15:04:38 IST" duration-ms="12424" status="SKIP">
          <params>
            <param index="0">
              <value>
                <![CDATA[pavanoltraining@gmail.com]]>
              </value>
            </param>
            <param index="1">
              <value>
                <![CDATA[test@123]]>
              </value>
            </param>
            <param index="2">
              <value>
                <![CDATA[Valid]]>
              </value>
            </param>
          </params>
          <exception class="java.lang.AssertionError">
            <message>
              <![CDATA[expected [true] but found [false]]]>
            </message>
            <full-stacktrace>
              <![CDATA[java.lang.AssertionError: expected [true] but found [false]
at org.testng.Assert.fail(Assert.java:111)
at org.testng.Assert.failNotEquals(Assert.java:1578)
at org.testng.Assert.assertTrue(Assert.java:57)
at org.testng.Assert.assertTrue(Assert.java:67)
at testCases.TC004_LoginDataDrivenTest.validate_login(TC004_LoginDataDrivenTest.java:67)
at java.base/jdk.internal.reflect.DirectMethodHandleAccessor.invoke(DirectMethodHandleAccessor.java:103)
at java.base/java.lang.reflect.Method.invoke(Method.java:580)
at org.testng.internal.invokers.MethodInvocationHelper.invokeMethod(MethodInvocationHelper.java:139)
at org.testng.internal.invokers.TestInvoker.invokeMethod(TestInvoker.java:664)
at org.testng.internal.invokers.TestInvoker.invokeTestMethod(TestInvoker.java:227)
at org.testng.internal.invokers.MethodRunner.runInSequence(MethodRunner.java:50)
at org.testng.internal.invokers.TestInvoker$MethodInvocationAgent.invoke(TestInvoker.java:957)
at org.testng.internal.invokers.TestInvoker.invokeTestMethods(TestInvoker.java:200)
at org.testng.internal.invokers.TestMethodWorker.invokeTestMethods(TestMethodWorker.java:148)
at org.testng.internal.invokers.TestMethodWorker.run(TestMethodWorker.java:128)
at java.base/java.util.ArrayList.forEach(ArrayList.java:1597)
at org.testng.TestRunner.privateRun(TestRunner.java:848)
at org.testng.TestRunner.run(TestRunner.java:621)
at org.testng.SuiteRunner.runTest(SuiteRunner.java:443)
at org.testng.SuiteRunner.runSequentially(SuiteRunner.java:437)
at org.testng.SuiteRunner.privateRun(SuiteRunner.java:397)
at org.testng.SuiteRunner.run(SuiteRunner.java:336)
at org.testng.SuiteRunnerWorker.runSuite(SuiteRunnerWorker.java:52)
at org.testng.SuiteRunnerWorker.run(SuiteRunnerWorker.java:95)
at org.testng.TestNG.runSuitesSequentially(TestNG.java:1280)
at org.testng.TestNG.runSuitesLocally(TestNG.java:1200)
at org.testng.TestNG.runSuites(TestNG.java:1114)
at org.testng.TestNG.run(TestNG.java:1082)
at org.testng.remote.AbstractRemoteTestNG.run(AbstractRemoteTestNG.java:115)
at org.testng.remote.RemoteTestNG.initAndRun(RemoteTestNG.java:293)
at org.testng.remote.RemoteTestNG.main(RemoteTestNG.java:91)
]]>
            </full-stacktrace>
          </exception> <!-- java.lang.AssertionError -->
          <reporter-output>
          </reporter-output>
        </test-method> <!-- validate_login -->
        <test-method is-config="true" signature="resetTest()[pri:0, instance:testCases.TC004_LoginDataDrivenTest@246f8b8b]" started-at="2025-01-16T15:04:38 IST" name="resetTest" finished-at="2025-01-16T15:04:39 IST" duration-ms="957" status="PASS">
          <reporter-output>
          </reporter-output>
        </test-method> <!-- resetTest -->
        <test-method retried="true" signature="validate_login(java.lang.String,java.lang.String,java.lang.String)[pri:0, instance:testCases.TC004_LoginDataDrivenTest@246f8b8b]" started-at="2025-01-16T15:04:39 IST" name="validate_login" data-provider="loginDataProvider" finished-at="2025-01-16T15:04:52 IST" duration-ms="13067" status="SKIP">
          <params>
            <param index="0">
              <value>
                <![CDATA[pavanoltraining@gmail.com]]>
              </value>
            </param>
            <param index="1">
              <value>
                <![CDATA[test@123]]>
              </value>
            </param>
            <param index="2">
              <value>
                <![CDATA[Valid]]>
              </value>
            </param>
          </params>
          <exception class="java.lang.AssertionError">
            <message>
              <![CDATA[expected [true] but found [false]]]>
            </message>
            <full-stacktrace>
              <![CDATA[java.lang.AssertionError: expected [true] but found [false]
at org.testng.Assert.fail(Assert.java:111)
at org.testng.Assert.failNotEquals(Assert.java:1578)
at org.testng.Assert.assertTrue(Assert.java:57)
at org.testng.Assert.assertTrue(Assert.java:67)
at testCases.TC004_LoginDataDrivenTest.validate_login(TC004_LoginDataDrivenTest.java:67)
at java.base/jdk.internal.reflect.DirectMethodHandleAccessor.invoke(DirectMethodHandleAccessor.java:103)
at java.base/java.lang.reflect.Method.invoke(Method.java:580)
at org.testng.internal.invokers.MethodInvocationHelper.invokeMethod(MethodInvocationHelper.java:139)
at org.testng.internal.invokers.TestInvoker.invokeMethod(TestInvoker.java:664)
at org.testng.internal.invokers.TestInvoker.retryFailed(TestInvoker.java:248)
at org.testng.internal.invokers.MethodRunner.runInSequence(MethodRunner.java:62)
at org.testng.internal.invokers.TestInvoker$MethodInvocationAgent.invoke(TestInvoker.java:957)
at org.testng.internal.invokers.TestInvoker.invokeTestMethods(TestInvoker.java:200)
at org.testng.internal.invokers.TestMethodWorker.invokeTestMethods(TestMethodWorker.java:148)
at org.testng.internal.invokers.TestMethodWorker.run(TestMethodWorker.java:128)
at java.base/java.util.ArrayList.forEach(ArrayList.java:1597)
at org.testng.TestRunner.privateRun(TestRunner.java:848)
at org.testng.TestRunner.run(TestRunner.java:621)
at org.testng.SuiteRunner.runTest(SuiteRunner.java:443)
at org.testng.SuiteRunner.runSequentially(SuiteRunner.java:437)
at org.testng.SuiteRunner.privateRun(SuiteRunner.java:397)
at org.testng.SuiteRunner.run(SuiteRunner.java:336)
at org.testng.SuiteRunnerWorker.runSuite(SuiteRunnerWorker.java:52)
at org.testng.SuiteRunnerWorker.run(SuiteRunnerWorker.java:95)
at org.testng.TestNG.runSuitesSequentially(TestNG.java:1280)
at org.testng.TestNG.runSuitesLocally(TestNG.java:1200)
at org.testng.TestNG.runSuites(TestNG.java:1114)
at org.testng.TestNG.run(TestNG.java:1082)
at org.testng.remote.AbstractRemoteTestNG.run(AbstractRemoteTestNG.java:115)
at org.testng.remote.RemoteTestNG.initAndRun(RemoteTestNG.java:293)
at org.testng.remote.RemoteTestNG.main(RemoteTestNG.java:91)
]]>
            </full-stacktrace>
          </exception> <!-- java.lang.AssertionError -->
          <reporter-output>
          </reporter-output>
        </test-method> <!-- validate_login -->
        <test-method is-config="true" signature="resetTest()[pri:0, instance:testCases.TC004_LoginDataDrivenTest@246f8b8b]" started-at="2025-01-16T15:04:52 IST" name="resetTest" finished-at="2025-01-16T15:04:52 IST" duration-ms="407" status="PASS">
          <reporter-output>
          </reporter-output>
        </test-method> <!-- resetTest -->
        <test-method signature="validate_login(java.lang.String,java.lang.String,java.lang.String)[pri:0, instance:testCases.TC004_LoginDataDrivenTest@246f8b8b]" started-at="2025-01-16T15:04:52 IST" name="validate_login" data-provider="loginDataProvider" finished-at="2025-01-16T15:05:05 IST" duration-ms="12834" status="FAIL">
          <params>
            <param index="0">
              <value>
                <![CDATA[pavanoltraining@gmail.com]]>
              </value>
            </param>
            <param index="1">
              <value>
                <![CDATA[test@123]]>
              </value>
            </param>
            <param index="2">
              <value>
                <![CDATA[Valid]]>
              </value>
            </param>
          </params>
          <exception class="java.lang.AssertionError">
            <message>
              <![CDATA[expected [true] but found [false]]]>
            </message>
            <full-stacktrace>
              <![CDATA[java.lang.AssertionError: expected [true] but found [false]
at org.testng.Assert.fail(Assert.java:111)
at org.testng.Assert.failNotEquals(Assert.java:1578)
at org.testng.Assert.assertTrue(Assert.java:57)
at org.testng.Assert.assertTrue(Assert.java:67)
at testCases.TC004_LoginDataDrivenTest.validate_login(TC004_LoginDataDrivenTest.java:67)
at java.base/jdk.internal.reflect.DirectMethodHandleAccessor.invoke(DirectMethodHandleAccessor.java:103)
at java.base/java.lang.reflect.Method.invoke(Method.java:580)
at org.testng.internal.invokers.MethodInvocationHelper.invokeMethod(MethodInvocationHelper.java:139)
at org.testng.internal.invokers.TestInvoker.invokeMethod(TestInvoker.java:664)
at org.testng.internal.invokers.TestInvoker.retryFailed(TestInvoker.java:248)
at org.testng.internal.invokers.MethodRunner.runInSequence(MethodRunner.java:62)
at org.testng.internal.invokers.TestInvoker$MethodInvocationAgent.invoke(TestInvoker.java:957)
at org.testng.internal.invokers.TestInvoker.invokeTestMethods(TestInvoker.java:200)
at org.testng.internal.invokers.TestMethodWorker.invokeTestMethods(TestMethodWorker.java:148)
at org.testng.internal.invokers.TestMethodWorker.run(TestMethodWorker.java:128)
at java.base/java.util.ArrayList.forEach(ArrayList.java:1597)
at org.testng.TestRunner.privateRun(TestRunner.java:848)
at org.testng.TestRunner.run(TestRunner.java:621)
at org.testng.SuiteRunner.runTest(SuiteRunner.java:443)
at org.testng.SuiteRunner.runSequentially(SuiteRunner.java:437)
at org.testng.SuiteRunner.privateRun(SuiteRunner.java:397)
at org.testng.SuiteRunner.run(SuiteRunner.java:336)
at org.testng.SuiteRunnerWorker.runSuite(SuiteRunnerWorker.java:52)
at org.testng.SuiteRunnerWorker.run(SuiteRunnerWorker.java:95)
at org.testng.TestNG.runSuitesSequentially(TestNG.java:1280)
at org.testng.TestNG.runSuitesLocally(TestNG.java:1200)
at org.testng.TestNG.runSuites(TestNG.java:1114)
at org.testng.TestNG.run(TestNG.java:1082)
at org.testng.remote.AbstractRemoteTestNG.run(AbstractRemoteTestNG.java:115)
at org.testng.remote.RemoteTestNG.initAndRun(RemoteTestNG.java:293)
at org.testng.remote.RemoteTestNG.main(RemoteTestNG.java:91)
]]>
            </full-stacktrace>
          </exception> <!-- java.lang.AssertionError -->
          <reporter-output>
          </reporter-output>
        </test-method> <!-- validate_login -->
        <test-method is-config="true" signature="resetTest()[pri:0, instance:testCases.TC004_LoginDataDrivenTest@246f8b8b]" started-at="2025-01-16T15:05:06 IST" name="resetTest" finished-at="2025-01-16T15:05:06 IST" duration-ms="672" status="PASS">
          <reporter-output>
          </reporter-output>
        </test-method> <!-- resetTest -->
        <test-method retried="true" signature="validate_login(java.lang.String,java.lang.String,java.lang.String)[pri:0, instance:testCases.TC004_LoginDataDrivenTest@246f8b8b]" started-at="2025-01-16T15:05:06 IST" name="validate_login" data-provider="loginDataProvider" finished-at="2025-01-16T15:05:10 IST" duration-ms="3358" status="SKIP">
          <params>
            <param index="0">
              <value>
                <![CDATA[lakshmi@yahoo.com]]>
              </value>
            </param>
            <param index="1">
              <value>
                <![CDATA[Laxmi]]>
              </value>
            </param>
            <param index="2">
              <value>
                <![CDATA[Invalid]]>
              </value>
            </param>
          </params>
          <exception class="java.lang.AssertionError">
            <message>
              <![CDATA[expected [true] but found [false]]]>
            </message>
            <full-stacktrace>
              <![CDATA[java.lang.AssertionError: expected [true] but found [false]
at org.testng.Assert.fail(Assert.java:111)
at org.testng.Assert.failNotEquals(Assert.java:1578)
at org.testng.Assert.assertTrue(Assert.java:57)
at org.testng.Assert.assertTrue(Assert.java:67)
at testCases.TC004_LoginDataDrivenTest.validate_login(TC004_LoginDataDrivenTest.java:82)
at java.base/jdk.internal.reflect.DirectMethodHandleAccessor.invoke(DirectMethodHandleAccessor.java:103)
at java.base/java.lang.reflect.Method.invoke(Method.java:580)
at org.testng.internal.invokers.MethodInvocationHelper.invokeMethod(MethodInvocationHelper.java:139)
at org.testng.internal.invokers.TestInvoker.invokeMethod(TestInvoker.java:664)
at org.testng.internal.invokers.TestInvoker.invokeTestMethod(TestInvoker.java:227)
at org.testng.internal.invokers.MethodRunner.runInSequence(MethodRunner.java:50)
at org.testng.internal.invokers.TestInvoker$MethodInvocationAgent.invoke(TestInvoker.java:957)
at org.testng.internal.invokers.TestInvoker.invokeTestMethods(TestInvoker.java:200)
at org.testng.internal.invokers.TestMethodWorker.invokeTestMethods(TestMethodWorker.java:148)
at org.testng.internal.invokers.TestMethodWorker.run(TestMethodWorker.java:128)
at java.base/java.util.ArrayList.forEach(ArrayList.java:1597)
at org.testng.TestRunner.privateRun(TestRunner.java:848)
at org.testng.TestRunner.run(TestRunner.java:621)
at org.testng.SuiteRunner.runTest(SuiteRunner.java:443)
at org.testng.SuiteRunner.runSequentially(SuiteRunner.java:437)
at org.testng.SuiteRunner.privateRun(SuiteRunner.java:397)
at org.testng.SuiteRunner.run(SuiteRunner.java:336)
at org.testng.SuiteRunnerWorker.runSuite(SuiteRunnerWorker.java:52)
at org.testng.SuiteRunnerWorker.run(SuiteRunnerWorker.java:95)
at org.testng.TestNG.runSuitesSequentially(TestNG.java:1280)
at org.testng.TestNG.runSuitesLocally(TestNG.java:1200)
at org.testng.TestNG.runSuites(TestNG.java:1114)
at org.testng.TestNG.run(TestNG.java:1082)
at org.testng.remote.AbstractRemoteTestNG.run(AbstractRemoteTestNG.java:115)
at org.testng.remote.RemoteTestNG.initAndRun(RemoteTestNG.java:293)
at org.testng.remote.RemoteTestNG.main(RemoteTestNG.java:91)
]]>
            </full-stacktrace>
          </exception> <!-- java.lang.AssertionError -->
          <reporter-output>
          </reporter-output>
        </test-method> <!-- validate_login -->
        <test-method is-config="true" signature="resetTest()[pri:0, instance:testCases.TC004_LoginDataDrivenTest@246f8b8b]" started-at="2025-01-16T15:05:10 IST" name="resetTest" finished-at="2025-01-16T15:05:10 IST" duration-ms="877" status="PASS">
          <reporter-output>
          </reporter-output>
        </test-method> <!-- resetTest -->
        <test-method retried="true" signature="validate_login(java.lang.String,java.lang.String,java.lang.String)[pri:0, instance:testCases.TC004_LoginDataDrivenTest@246f8b8b]" started-at="2025-01-16T15:05:10 IST" name="validate_login" data-provider="loginDataProvider" finished-at="2025-01-16T15:05:14 IST" duration-ms="3169" status="SKIP">
          <params>
            <param index="0">
              <value>
                <![CDATA[lakshmi@yahoo.com]]>
              </value>
            </param>
            <param index="1">
              <value>
                <![CDATA[Laxmi]]>
              </value>
            </param>
            <param index="2">
              <value>
                <![CDATA[Invalid]]>
              </value>
            </param>
          </params>
          <exception class="java.lang.AssertionError">
            <message>
              <![CDATA[expected [true] but found [false]]]>
            </message>
            <full-stacktrace>
              <![CDATA[java.lang.AssertionError: expected [true] but found [false]
at org.testng.Assert.fail(Assert.java:111)
at org.testng.Assert.failNotEquals(Assert.java:1578)
at org.testng.Assert.assertTrue(Assert.java:57)
at org.testng.Assert.assertTrue(Assert.java:67)
at testCases.TC004_LoginDataDrivenTest.validate_login(TC004_LoginDataDrivenTest.java:82)
at java.base/jdk.internal.reflect.DirectMethodHandleAccessor.invoke(DirectMethodHandleAccessor.java:103)
at java.base/java.lang.reflect.Method.invoke(Method.java:580)
at org.testng.internal.invokers.MethodInvocationHelper.invokeMethod(MethodInvocationHelper.java:139)
at org.testng.internal.invokers.TestInvoker.invokeMethod(TestInvoker.java:664)
at org.testng.internal.invokers.TestInvoker.retryFailed(TestInvoker.java:248)
at org.testng.internal.invokers.MethodRunner.runInSequence(MethodRunner.java:62)
at org.testng.internal.invokers.TestInvoker$MethodInvocationAgent.invoke(TestInvoker.java:957)
at org.testng.internal.invokers.TestInvoker.invokeTestMethods(TestInvoker.java:200)
at org.testng.internal.invokers.TestMethodWorker.invokeTestMethods(TestMethodWorker.java:148)
at org.testng.internal.invokers.TestMethodWorker.run(TestMethodWorker.java:128)
at java.base/java.util.ArrayList.forEach(ArrayList.java:1597)
at org.testng.TestRunner.privateRun(TestRunner.java:848)
at org.testng.TestRunner.run(TestRunner.java:621)
at org.testng.SuiteRunner.runTest(SuiteRunner.java:443)
at org.testng.SuiteRunner.runSequentially(SuiteRunner.java:437)
at org.testng.SuiteRunner.privateRun(SuiteRunner.java:397)
at org.testng.SuiteRunner.run(SuiteRunner.java:336)
at org.testng.SuiteRunnerWorker.runSuite(SuiteRunnerWorker.java:52)
at org.testng.SuiteRunnerWorker.run(SuiteRunnerWorker.java:95)
at org.testng.TestNG.runSuitesSequentially(TestNG.java:1280)
at org.testng.TestNG.runSuitesLocally(TestNG.java:1200)
at org.testng.TestNG.runSuites(TestNG.java:1114)
at org.testng.TestNG.run(TestNG.java:1082)
at org.testng.remote.AbstractRemoteTestNG.run(AbstractRemoteTestNG.java:115)
at org.testng.remote.RemoteTestNG.initAndRun(RemoteTestNG.java:293)
at org.testng.remote.RemoteTestNG.main(RemoteTestNG.java:91)
]]>
            </full-stacktrace>
          </exception> <!-- java.lang.AssertionError -->
          <reporter-output>
          </reporter-output>
        </test-method> <!-- validate_login -->
        <test-method is-config="true" signature="resetTest()[pri:0, instance:testCases.TC004_LoginDataDrivenTest@246f8b8b]" started-at="2025-01-16T15:05:14 IST" name="resetTest" finished-at="2025-01-16T15:05:14 IST" duration-ms="468" status="PASS">
          <reporter-output>
          </reporter-output>
        </test-method> <!-- resetTest -->
        <test-method signature="validate_login(java.lang.String,java.lang.String,java.lang.String)[pri:0, instance:testCases.TC004_LoginDataDrivenTest@246f8b8b]" started-at="2025-01-16T15:05:14 IST" name="validate_login" data-provider="loginDataProvider" finished-at="2025-01-16T15:05:18 IST" duration-ms="3774" status="FAIL">
          <params>
            <param index="0">
              <value>
                <![CDATA[lakshmi@yahoo.com]]>
              </value>
            </param>
            <param index="1">
              <value>
                <![CDATA[Laxmi]]>
              </value>
            </param>
            <param index="2">
              <value>
                <![CDATA[Invalid]]>
              </value>
            </param>
          </params>
          <exception class="java.lang.AssertionError">
            <message>
              <![CDATA[expected [true] but found [false]]]>
            </message>
            <full-stacktrace>
              <![CDATA[java.lang.AssertionError: expected [true] but found [false]
at org.testng.Assert.fail(Assert.java:111)
at org.testng.Assert.failNotEquals(Assert.java:1578)
at org.testng.Assert.assertTrue(Assert.java:57)
at org.testng.Assert.assertTrue(Assert.java:67)
at testCases.TC004_LoginDataDrivenTest.validate_login(TC004_LoginDataDrivenTest.java:82)
at java.base/jdk.internal.reflect.DirectMethodHandleAccessor.invoke(DirectMethodHandleAccessor.java:103)
at java.base/java.lang.reflect.Method.invoke(Method.java:580)
at org.testng.internal.invokers.MethodInvocationHelper.invokeMethod(MethodInvocationHelper.java:139)
at org.testng.internal.invokers.TestInvoker.invokeMethod(TestInvoker.java:664)
at org.testng.internal.invokers.TestInvoker.retryFailed(TestInvoker.java:248)
at org.testng.internal.invokers.MethodRunner.runInSequence(MethodRunner.java:62)
at org.testng.internal.invokers.TestInvoker$MethodInvocationAgent.invoke(TestInvoker.java:957)
at org.testng.internal.invokers.TestInvoker.invokeTestMethods(TestInvoker.java:200)
at org.testng.internal.invokers.TestMethodWorker.invokeTestMethods(TestMethodWorker.java:148)
at org.testng.internal.invokers.TestMethodWorker.run(TestMethodWorker.java:128)
at java.base/java.util.ArrayList.forEach(ArrayList.java:1597)
at org.testng.TestRunner.privateRun(TestRunner.java:848)
at org.testng.TestRunner.run(TestRunner.java:621)
at org.testng.SuiteRunner.runTest(SuiteRunner.java:443)
at org.testng.SuiteRunner.runSequentially(SuiteRunner.java:437)
at org.testng.SuiteRunner.privateRun(SuiteRunner.java:397)
at org.testng.SuiteRunner.run(SuiteRunner.java:336)
at org.testng.SuiteRunnerWorker.runSuite(SuiteRunnerWorker.java:52)
at org.testng.SuiteRunnerWorker.run(SuiteRunnerWorker.java:95)
at org.testng.TestNG.runSuitesSequentially(TestNG.java:1280)
at org.testng.TestNG.runSuitesLocally(TestNG.java:1200)
at org.testng.TestNG.runSuites(TestNG.java:1114)
at org.testng.TestNG.run(TestNG.java:1082)
at org.testng.remote.AbstractRemoteTestNG.run(AbstractRemoteTestNG.java:115)
at org.testng.remote.RemoteTestNG.initAndRun(RemoteTestNG.java:293)
at org.testng.remote.RemoteTestNG.main(RemoteTestNG.java:91)
]]>
            </full-stacktrace>
          </exception> <!-- java.lang.AssertionError -->
          <reporter-output>
          </reporter-output>
        </test-method> <!-- validate_login -->
        <test-method is-config="true" signature="resetTest()[pri:0, instance:testCases.TC004_LoginDataDrivenTest@246f8b8b]" started-at="2025-01-16T15:05:18 IST" name="resetTest" finished-at="2025-01-16T15:05:19 IST" duration-ms="932" status="PASS">
          <reporter-output>
          </reporter-output>
        </test-method> <!-- resetTest -->
        <test-method retried="true" signature="validate_login(java.lang.String,java.lang.String,java.lang.String)[pri:0, instance:testCases.TC004_LoginDataDrivenTest@246f8b8b]" started-at="2025-01-16T15:05:19 IST" name="validate_login" data-provider="loginDataProvider" finished-at="2025-01-16T15:05:23 IST" duration-ms="3761" status="SKIP">
          <params>
            <param index="0">
              <value>
                <![CDATA[laksh@yahoo.com]]>
              </value>
            </param>
            <param index="1">
              <value>
                <![CDATA[Lakshmi]]>
              </value>
            </param>
            <param index="2">
              <value>
                <![CDATA[Invalid]]>
              </value>
            </param>
          </params>
          <exception class="java.lang.AssertionError">
            <message>
              <![CDATA[expected [true] but found [false]]]>
            </message>
            <full-stacktrace>
              <![CDATA[java.lang.AssertionError: expected [true] but found [false]
at org.testng.Assert.fail(Assert.java:111)
at org.testng.Assert.failNotEquals(Assert.java:1578)
at org.testng.Assert.assertTrue(Assert.java:57)
at org.testng.Assert.assertTrue(Assert.java:67)
at testCases.TC004_LoginDataDrivenTest.validate_login(TC004_LoginDataDrivenTest.java:82)
at java.base/jdk.internal.reflect.DirectMethodHandleAccessor.invoke(DirectMethodHandleAccessor.java:103)
at java.base/java.lang.reflect.Method.invoke(Method.java:580)
at org.testng.internal.invokers.MethodInvocationHelper.invokeMethod(MethodInvocationHelper.java:139)
at org.testng.internal.invokers.TestInvoker.invokeMethod(TestInvoker.java:664)
at org.testng.internal.invokers.TestInvoker.invokeTestMethod(TestInvoker.java:227)
at org.testng.internal.invokers.MethodRunner.runInSequence(MethodRunner.java:50)
at org.testng.internal.invokers.TestInvoker$MethodInvocationAgent.invoke(TestInvoker.java:957)
at org.testng.internal.invokers.TestInvoker.invokeTestMethods(TestInvoker.java:200)
at org.testng.internal.invokers.TestMethodWorker.invokeTestMethods(TestMethodWorker.java:148)
at org.testng.internal.invokers.TestMethodWorker.run(TestMethodWorker.java:128)
at java.base/java.util.ArrayList.forEach(ArrayList.java:1597)
at org.testng.TestRunner.privateRun(TestRunner.java:848)
at org.testng.TestRunner.run(TestRunner.java:621)
at org.testng.SuiteRunner.runTest(SuiteRunner.java:443)
at org.testng.SuiteRunner.runSequentially(SuiteRunner.java:437)
at org.testng.SuiteRunner.privateRun(SuiteRunner.java:397)
at org.testng.SuiteRunner.run(SuiteRunner.java:336)
at org.testng.SuiteRunnerWorker.runSuite(SuiteRunnerWorker.java:52)
at org.testng.SuiteRunnerWorker.run(SuiteRunnerWorker.java:95)
at org.testng.TestNG.runSuitesSequentially(TestNG.java:1280)
at org.testng.TestNG.runSuitesLocally(TestNG.java:1200)
at org.testng.TestNG.runSuites(TestNG.java:1114)
at org.testng.TestNG.run(TestNG.java:1082)
at org.testng.remote.AbstractRemoteTestNG.run(AbstractRemoteTestNG.java:115)
at org.testng.remote.RemoteTestNG.initAndRun(RemoteTestNG.java:293)
at org.testng.remote.RemoteTestNG.main(RemoteTestNG.java:91)
]]>
            </full-stacktrace>
          </exception> <!-- java.lang.AssertionError -->
          <reporter-output>
          </reporter-output>
        </test-method> <!-- validate_login -->
        <test-method is-config="true" signature="resetTest()[pri:0, instance:testCases.TC004_LoginDataDrivenTest@246f8b8b]" started-at="2025-01-16T15:05:23 IST" name="resetTest" finished-at="2025-01-16T15:05:24 IST" duration-ms="977" status="PASS">
          <reporter-output>
          </reporter-output>
        </test-method> <!-- resetTest -->
        <test-method retried="true" signature="validate_login(java.lang.String,java.lang.String,java.lang.String)[pri:0, instance:testCases.TC004_LoginDataDrivenTest@246f8b8b]" started-at="2025-01-16T15:05:24 IST" name="validate_login" data-provider="loginDataProvider" finished-at="2025-01-16T15:05:28 IST" duration-ms="3918" status="SKIP">
          <params>
            <param index="0">
              <value>
                <![CDATA[laksh@yahoo.com]]>
              </value>
            </param>
            <param index="1">
              <value>
                <![CDATA[Lakshmi]]>
              </value>
            </param>
            <param index="2">
              <value>
                <![CDATA[Invalid]]>
              </value>
            </param>
          </params>
          <exception class="java.lang.AssertionError">
            <message>
              <![CDATA[expected [true] but found [false]]]>
            </message>
            <full-stacktrace>
              <![CDATA[java.lang.AssertionError: expected [true] but found [false]
at org.testng.Assert.fail(Assert.java:111)
at org.testng.Assert.failNotEquals(Assert.java:1578)
at org.testng.Assert.assertTrue(Assert.java:57)
at org.testng.Assert.assertTrue(Assert.java:67)
at testCases.TC004_LoginDataDrivenTest.validate_login(TC004_LoginDataDrivenTest.java:82)
at java.base/jdk.internal.reflect.DirectMethodHandleAccessor.invoke(DirectMethodHandleAccessor.java:103)
at java.base/java.lang.reflect.Method.invoke(Method.java:580)
at org.testng.internal.invokers.MethodInvocationHelper.invokeMethod(MethodInvocationHelper.java:139)
at org.testng.internal.invokers.TestInvoker.invokeMethod(TestInvoker.java:664)
at org.testng.internal.invokers.TestInvoker.retryFailed(TestInvoker.java:248)
at org.testng.internal.invokers.MethodRunner.runInSequence(MethodRunner.java:62)
at org.testng.internal.invokers.TestInvoker$MethodInvocationAgent.invoke(TestInvoker.java:957)
at org.testng.internal.invokers.TestInvoker.invokeTestMethods(TestInvoker.java:200)
at org.testng.internal.invokers.TestMethodWorker.invokeTestMethods(TestMethodWorker.java:148)
at org.testng.internal.invokers.TestMethodWorker.run(TestMethodWorker.java:128)
at java.base/java.util.ArrayList.forEach(ArrayList.java:1597)
at org.testng.TestRunner.privateRun(TestRunner.java:848)
at org.testng.TestRunner.run(TestRunner.java:621)
at org.testng.SuiteRunner.runTest(SuiteRunner.java:443)
at org.testng.SuiteRunner.runSequentially(SuiteRunner.java:437)
at org.testng.SuiteRunner.privateRun(SuiteRunner.java:397)
at org.testng.SuiteRunner.run(SuiteRunner.java:336)
at org.testng.SuiteRunnerWorker.runSuite(SuiteRunnerWorker.java:52)
at org.testng.SuiteRunnerWorker.run(SuiteRunnerWorker.java:95)
at org.testng.TestNG.runSuitesSequentially(TestNG.java:1280)
at org.testng.TestNG.runSuitesLocally(TestNG.java:1200)
at org.testng.TestNG.runSuites(TestNG.java:1114)
at org.testng.TestNG.run(TestNG.java:1082)
at org.testng.remote.AbstractRemoteTestNG.run(AbstractRemoteTestNG.java:115)
at org.testng.remote.RemoteTestNG.initAndRun(RemoteTestNG.java:293)
at org.testng.remote.RemoteTestNG.main(RemoteTestNG.java:91)
]]>
            </full-stacktrace>
          </exception> <!-- java.lang.AssertionError -->
          <reporter-output>
          </reporter-output>
        </test-method> <!-- validate_login -->
        <test-method is-config="true" signature="resetTest()[pri:0, instance:testCases.TC004_LoginDataDrivenTest@246f8b8b]" started-at="2025-01-16T15:05:28 IST" name="resetTest" finished-at="2025-01-16T15:05:29 IST" duration-ms="829" status="PASS">
          <reporter-output>
          </reporter-output>
        </test-method> <!-- resetTest -->
        <test-method signature="validate_login(java.lang.String,java.lang.String,java.lang.String)[pri:0, instance:testCases.TC004_LoginDataDrivenTest@246f8b8b]" started-at="2025-01-16T15:05:29 IST" name="validate_login" data-provider="loginDataProvider" finished-at="2025-01-16T15:05:33 IST" duration-ms="4090" status="FAIL">
          <params>
            <param index="0">
              <value>
                <![CDATA[laksh@yahoo.com]]>
              </value>
            </param>
            <param index="1">
              <value>
                <![CDATA[Lakshmi]]>
              </value>
            </param>
            <param index="2">
              <value>
                <![CDATA[Invalid]]>
              </value>
            </param>
          </params>
          <exception class="java.lang.AssertionError">
            <message>
              <![CDATA[expected [true] but found [false]]]>
            </message>
            <full-stacktrace>
              <![CDATA[java.lang.AssertionError: expected [true] but found [false]
at org.testng.Assert.fail(Assert.java:111)
at org.testng.Assert.failNotEquals(Assert.java:1578)
at org.testng.Assert.assertTrue(Assert.java:57)
at org.testng.Assert.assertTrue(Assert.java:67)
at testCases.TC004_LoginDataDrivenTest.validate_login(TC004_LoginDataDrivenTest.java:82)
at java.base/jdk.internal.reflect.DirectMethodHandleAccessor.invoke(DirectMethodHandleAccessor.java:103)
at java.base/java.lang.reflect.Method.invoke(Method.java:580)
at org.testng.internal.invokers.MethodInvocationHelper.invokeMethod(MethodInvocationHelper.java:139)
at org.testng.internal.invokers.TestInvoker.invokeMethod(TestInvoker.java:664)
at org.testng.internal.invokers.TestInvoker.retryFailed(TestInvoker.java:248)
at org.testng.internal.invokers.MethodRunner.runInSequence(MethodRunner.java:62)
at org.testng.internal.invokers.TestInvoker$MethodInvocationAgent.invoke(TestInvoker.java:957)
at org.testng.internal.invokers.TestInvoker.invokeTestMethods(TestInvoker.java:200)
at org.testng.internal.invokers.TestMethodWorker.invokeTestMethods(TestMethodWorker.java:148)
at org.testng.internal.invokers.TestMethodWorker.run(TestMethodWorker.java:128)
at java.base/java.util.ArrayList.forEach(ArrayList.java:1597)
at org.testng.TestRunner.privateRun(TestRunner.java:848)
at org.testng.TestRunner.run(TestRunner.java:621)
at org.testng.SuiteRunner.runTest(SuiteRunner.java:443)
at org.testng.SuiteRunner.runSequentially(SuiteRunner.java:437)
at org.testng.SuiteRunner.privateRun(SuiteRunner.java:397)
at org.testng.SuiteRunner.run(SuiteRunner.java:336)
at org.testng.SuiteRunnerWorker.runSuite(SuiteRunnerWorker.java:52)
at org.testng.SuiteRunnerWorker.run(SuiteRunnerWorker.java:95)
at org.testng.TestNG.runSuitesSequentially(TestNG.java:1280)
at org.testng.TestNG.runSuitesLocally(TestNG.java:1200)
at org.testng.TestNG.runSuites(TestNG.java:1114)
at org.testng.TestNG.run(TestNG.java:1082)
at org.testng.remote.AbstractRemoteTestNG.run(AbstractRemoteTestNG.java:115)
at org.testng.remote.RemoteTestNG.initAndRun(RemoteTestNG.java:293)
at org.testng.remote.RemoteTestNG.main(RemoteTestNG.java:91)
]]>
            </full-stacktrace>
          </exception> <!-- java.lang.AssertionError -->
          <reporter-output>
          </reporter-output>
        </test-method> <!-- validate_login -->
        <test-method is-config="true" signature="resetTest()[pri:0, instance:testCases.TC004_LoginDataDrivenTest@246f8b8b]" started-at="2025-01-16T15:05:33 IST" name="resetTest" finished-at="2025-01-16T15:05:34 IST" duration-ms="724" status="PASS">
          <reporter-output>
          </reporter-output>
        </test-method> <!-- resetTest -->
        <test-method signature="validate_login(java.lang.String,java.lang.String,java.lang.String)[pri:0, instance:testCases.TC004_LoginDataDrivenTest@246f8b8b]" started-at="2025-01-16T15:05:34 IST" name="validate_login" data-provider="loginDataProvider" finished-at="2025-01-16T15:05:46 IST" duration-ms="12820" status="PASS">
          <params>
            <param index="0">
              <value>
                <![CDATA[laks@yahoo.com]]>
              </value>
            </param>
            <param index="1">
              <value>
                <![CDATA[xyz]]>
              </value>
            </param>
            <param index="2">
              <value>
                <![CDATA[Invalid]]>
              </value>
            </param>
          </params>
          <reporter-output>
          </reporter-output>
        </test-method> <!-- validate_login -->
        <test-method is-config="true" signature="resetTest()[pri:0, instance:testCases.TC004_LoginDataDrivenTest@246f8b8b]" started-at="2025-01-16T15:05:46 IST" name="resetTest" finished-at="2025-01-16T15:05:47 IST" duration-ms="771" status="PASS">
          <reporter-output>
          </reporter-output>
        </test-method> <!-- resetTest -->
        <test-method signature="validate_login(java.lang.String,java.lang.String,java.lang.String)[pri:0, instance:testCases.TC004_LoginDataDrivenTest@246f8b8b]" started-at="2025-01-16T15:05:47 IST" name="validate_login" data-provider="loginDataProvider" finished-at="2025-01-16T15:05:52 IST" duration-ms="5041" status="PASS">
          <params>
            <param index="0">
              <value>
                <![CDATA[abc123@gmail.com]]>
              </value>
            </param>
            <param index="1">
              <value>
                <![CDATA[test@123]]>
              </value>
            </param>
            <param index="2">
              <value>
                <![CDATA[Valid]]>
              </value>
            </param>
          </params>
          <reporter-output>
          </reporter-output>
        </test-method> <!-- validate_login -->
        <test-method is-config="true" signature="resetTest()[pri:0, instance:testCases.TC004_LoginDataDrivenTest@246f8b8b]" started-at="2025-01-16T15:05:52 IST" name="resetTest" finished-at="2025-01-16T15:05:52 IST" duration-ms="296" status="PASS">
          <reporter-output>
          </reporter-output>
        </test-method> <!-- resetTest -->
        <test-method signature="validate_login(java.lang.String,java.lang.String,java.lang.String)[pri:0, instance:testCases.TC004_LoginDataDrivenTest@246f8b8b]" started-at="2025-01-16T15:05:52 IST" name="validate_login" data-provider="loginDataProvider" finished-at="2025-01-16T15:06:06 IST" duration-ms="13203" status="PASS">
          <params>
            <param index="0">
              <value>
                <![CDATA[]]>
              </value>
            </param>
            <param index="1">
              <value>
                <![CDATA[test324]]>
              </value>
            </param>
            <param index="2">
              <value>
                <![CDATA[Invalid]]>
              </value>
            </param>
          </params>
          <reporter-output>
          </reporter-output>
        </test-method> <!-- validate_login -->
        <test-method is-config="true" signature="resetTest()[pri:0, instance:testCases.TC004_LoginDataDrivenTest@246f8b8b]" started-at="2025-01-16T15:06:06 IST" name="resetTest" finished-at="2025-01-16T15:06:07 IST" duration-ms="1038" status="PASS">
          <reporter-output>
          </reporter-output>
        </test-method> <!-- resetTest -->
        <test-method is-config="true" signature="tearDown()[pri:0, instance:testCases.TC004_LoginDataDrivenTest@246f8b8b]" started-at="2025-01-16T15:06:07 IST" name="tearDown" finished-at="2025-01-16T15:06:07 IST" duration-ms="748" status="PASS">
          <reporter-output>
          </reporter-output>
        </test-method> <!-- tearDown -->
      </class> <!-- testCases.TC004_LoginDataDrivenTest -->
    </test> <!-- Data Driven Test -->
  </suite> <!-- MasterSuite -->
</testng-results>
